<?xml version="1.0"?>
<robot name="heale" xmlns:xacro="http://www.ros.org/wiki/xacro">

  <!-- Rubber Wheel Macro -->
  <xacro:macro name="rubber_wheel" params="frnt_or_bk lft_or_rght number ox oy oz roll pitch yaw ax ay az">

    <!-- Rubber Wheel link -->
    <link name="{frnt_or_bk}_${lft_or_rght}_${number}_rubber_wheel">
      <inertial>
        <origin xyz="-9.3675E-17 -1.0686E-15 1.3045E-15" rpy="0 0 0" />
        <mass value="0.0052688" />
        <inertia
          ixx="7.0476E-07" ixy="-5.6311E-09" ixz="5.6325E-09"
          iyy="4.4776E-07" iyz="2.5718E-07" izz="4.4764E-07" />
      </inertial>

      <visual>
        <origin xyz="0.0 0.0 0.0" rpy="0.7854 0 0" />
        <geometry>
          <mesh filename="package://mecanum_description/meshes/rb_1_${number}_.STL" />
        </geometry>
        <material name="blue">
          <color rgba="0.2 0.2 1 1"/>
        </material>
      </visual>

      <collision>
        <origin xyz="0.0 0.0 0.0" rpy="0.0 0.0 0.0" />
        <geometry>
          <mesh filename="package://mecanum_description/meshes/rb_1_${number}_.STL" />
        </geometry>
      </collision>
    </link>

    <!-- Joint -->
    <joint name="${frnt_or_bk}_${lft_or_rght}_${number}_rb_joint" type="continuous">
      <origin rpy="${roll} ${pitch} ${yaw}" xyz="${ox} ${oy} ${oz}" />
      <parent link="${frnt_or_bk}_${lft_or_rght}_wheel"/> 
      <child link="{frnt_or_bk}_${lft_or_rght}_${number}_rubber_wheel"/>
      <axis xyz="${ax} ${ay} ${az}" />
    </joint>

    <!-- Gazebo plugin params -->
    <gazebo reference="{frnt_or_bk}_${lft_or_rght}_${number}_rubber_wheel">
      <mu1>1e14</mu1>
      <mu2>1e14</mu2>
      <kp>1e12</kp>
      <kd>10.0</kd>
      <minDepth>0.001</minDepth>
      <maxVel>0.1</maxVel>
      <fdir1>0 1 0</fdir1>
    </gazebo>

  </xacro:macro>

</robot>
